<?xml version="1.0"?>
<robot>

    <macro name="arm_link" params="name">
        <link name="${name}">
            <inertial>
                <origin xyz="0.0 0.0 0.0" rpy="0.0 0.0 0.4"/>
                <mass value="57.904"/>
                <inertia ixx="12.679" ixy="0.0" ixz="0.0" iyy="12.679" iyz="0.0" izz="0.651"/>
            </inertial>
            
            <visual>
                <origin xyz="0.0 0.0 0.1" rpy="0.0 0.0 0.0"/>
                <geometry>
                    <cylinder radius="0.15" length="0.8"/>
                </geometry>
                <material name="orange"/>
            </visual>

            <collision>
                <origin xyz="0.0 0.0 0.1" rpy="0.0 0.0 0.0"/>
                <geometry>
                    <cylinder radius="0.15" length="0.8"/>
                </geometry>
            
            </collision>
        </link>
    </macro>

    <macro name="arm_joint" params="name parent child axis">
        <joint name="${name}_joint" type="revolute">
            <origin xyz="0.0 0.0 0.6" rpy="0.0 0.0 0.0"/>
            <parent link="${parent}"/>
            <child link="${child}"/>
            <axis xyz="${axis}"/>
            <limit lower="-3.14" upper="3.14" effort="1000.0" velocity="0.5"/>
        </joint>
    </macro>


    <macro name="joint_trans" params="name ">
        <transmission name="${name}_trans">
            <type>transmission_interface/SimpleTransmission</type>
            <joint name="${name}">
                <hardwareInterface>EffortJointInterface</hardwareInterface>
            </joint>
            <actuator name="${name}_motor">
                <mechanicalReduction>1</mechanicalReduction>
                <hardwareInterface>EffortJointInterface</hardwareInterface>
            </actuator>
        </transmission>

    </macro>

</robot>